#VRML_SIM R2023a utf8

EXTERNPROTO "https://raw.githubusercontent.com/cyberbotics/webots/R2023a/projects/objects/backgrounds/protos/TexturedBackground.proto"
EXTERNPROTO "https://raw.githubusercontent.com/cyberbotics/webots/R2023a/projects/objects/backgrounds/protos/TexturedBackgroundLight.proto"
EXTERNPROTO "https://raw.githubusercontent.com/cyberbotics/webots/R2023a/projects/objects/floors/protos/RectangleArena.proto"

WorldInfo {
  basicTimeStep 8
}
Viewpoint {
  orientation -0.10512143382454538 0.7339209128281896 0.671051099294315 0.4206076504735037
  position -1.0740092021448113 -0.5261518185982759 0.769569460266559
}
TexturedBackground {
}
TexturedBackgroundLight {
}
RectangleArena {
  floorSize 2 2
}
Robot {
  translation 0 0 0.01
  rotation 0 1 0 0
  children [
    HingeJoint {
      jointParameters HingeJointParameters {
        axis 0 0 -1
      }
      device [
        RotationalMotor {
          name "motor_yaw"
        }
      ]
      endPoint Solid {
        translation 0 0 0.02
        rotation 0 0 -1 0
        children [
          Solid {
            translation 0 0.02 0.04
            rotation 1 0 0 1.5708
            children [
              HingeJoint {
                jointParameters HingeJointParameters {
                  axis 0 0 1
                }
                device [
                  RotationalMotor {
                    name "motor_pit"
                  }
                ]
                endPoint Solid {
                  translation 0 0 0.02
                  rotation 0 1 0 1.5708
                  children [
                    Solid {
                      translation 0 0 0.66
                      children [
                        Shape {
                          appearance Appearance {
                            material Material {
                              diffuseColor 0 1 0
                              transparency 0.3
                            }
                          }
                          geometry Cylinder {
                            height 1.3
                            radius 0.001
                          }
                        }
                      ]
                    }
                    Shape {
                      appearance Appearance {
                        material Material {
                          diffuseColor 0.192157 0.192157 0.192157
                        }
                      }
                      geometry Cylinder {
                        height 0.04
                        radius 0.005
                      }
                    }
                  ]
                }
              }
              Shape {
                appearance Appearance {
                  material Material {
                    diffuseColor 0.427451 0.427451 0.427451
                  }
                }
                geometry Cylinder {
                  height 0.02
                  radius 0.02
                }
              }
            ]
          }
          Shape {
            appearance Appearance {
              material Material {
                diffuseColor 0.254902 0.254902 0.254902
              }
            }
            geometry Cylinder {
              height 0.02
              radius 0.02
            }
          }
        ]
      }
    }
    Shape {
      appearance Appearance {
        material Material {
        }
      }
      geometry Box {
        size 0.15 0.3 0.02
      }
    }
  ]
  controller "controller1"
}
Transform {
  translation 1.0001 0 0.5
  children [
    Shape {
      appearance Appearance {
        material Material {
          diffuseColor 1 1 1
        }
      }
      geometry Box {
        size 0.001 1 1
      }
    }
  ]
}
Transform {
  translation 1 0 0.5
  children [
    Shape {
      appearance Appearance {
        material Material {
          diffuseColor 0.890196 0.890196 0.890196
        }
      }
      geometry Box {
        size 0.001 0.5 0.5
      }
    }
  ]
}
