#VRML_SIM R2023a utf8

EXTERNPROTO "https://raw.githubusercontent.com/cyberbotics/webots/R2023a/projects/objects/backgrounds/protos/TexturedBackground.proto"
EXTERNPROTO "https://raw.githubusercontent.com/cyberbotics/webots/R2023a/projects/objects/backgrounds/protos/TexturedBackgroundLight.proto"
EXTERNPROTO "https://raw.githubusercontent.com/cyberbotics/webots/R2023a/projects/objects/floors/protos/RectangleArena.proto"

WorldInfo {
  basicTimeStep 8
}
Viewpoint {
  orientation 0.0009544255570270295 0.998198583744118 -0.05998896967854332 0.028350040638336033
  position -1.3812254773683925 0.06942842668894379 0.5536733507765323
}
TexturedBackground {
}
TexturedBackgroundLight {
}
RectangleArena {
  floorSize 2 2
}
Robot {
  translation 0 -0.6 0.01
  rotation 0 1 0 0
  children [
    HingeJoint {
      jointParameters HingeJointParameters {
        axis 0 0 -1
      }
      device [
        RotationalMotor {
          name "motor_yaw"
        }
      ]
      endPoint Solid {
        translation 0 0 0.02
        rotation 0 0 -1 0
        children [
          Solid {
            translation 0 0.02 0.04
            rotation 1 0 0 1.5708
            children [
              HingeJoint {
                jointParameters HingeJointParameters {
                  axis 0 0 1
                }
                device [
                  RotationalMotor {
                    name "motor_pit"
                  }
                ]
                endPoint Solid {
                  translation 0 0 0.02
                  rotation 0 1 0 1.5708
                  children [
                    Camera {
                      translation 0 0.02 0
                      rotation 0.5773509358560258 0.577349935856137 0.577349935856137 -2.094395307179586
                      children [
                        Shape {
                          appearance Appearance {
                            material Material {
                              diffuseColor 0.333333 0 1
                            }
                          }
                          geometry Cylinder {
                            height 0.03
                            radius 0.01
                          }
                        }
                      ]
                      fieldOfView 0.6
                      width 160
                      height 120
                    }
                    Solid {
                      translation 0 0 0.99
                      children [
                        Shape {
                          appearance Appearance {
                            material Material {
                              diffuseColor 0 1 0
                              transparency 0.8
                            }
                          }
                          geometry Cylinder {
                            radius 0.001
                          }
                        }
                      ]
                    }
                    Shape {
                      appearance Appearance {
                        material Material {
                          diffuseColor 0.192157 0.192157 0.192157
                        }
                      }
                      geometry Cylinder {
                        height 0.04
                        radius 0.005
                      }
                    }
                  ]
                }
              }
              Shape {
                appearance Appearance {
                  material Material {
                    diffuseColor 0.427451 0.427451 0.427451
                  }
                }
                geometry Cylinder {
                  height 0.02
                  radius 0.02
                }
              }
            ]
          }
          Shape {
            appearance Appearance {
              material Material {
                diffuseColor 0.254902 0.254902 0.254902
              }
            }
            geometry Cylinder {
              height 0.02
              radius 0.02
            }
          }
        ]
      }
    }
    Shape {
      appearance Appearance {
        material Material {
        }
      }
      geometry Box {
        size 0.15 0.3 0.02
      }
    }
  ]
  name "track"
  controller "controller_track"
}
Transform {
  translation 1.0001 0 0.5
  children [
    Shape {
      appearance Appearance {
        material Material {
          diffuseColor 0.780392 0.780392 0.780392
        }
      }
      geometry Box {
        size 0.001 1 1
      }
    }
  ]
}
Transform {
  translation 1 0 0.5
  children [
    Shape {
      appearance Appearance {
        material Material {
          diffuseColor 0.705882 0.705882 0.705882
        }
      }
      geometry Box {
        size 0.001 0.5 0.5
      }
    }
  ]
}
Transform {
  translation 0.9999 0.06 0.57
  rotation 0 1 0 -1.5707953071795862
  children [
    Shape {
      appearance Appearance {
        material Material {
          diffuseColor 1 0 0
        }
      }
      geometry Cylinder {
        height 0.001
        radius 0.005
      }
    }
  ]
}
